Workbook

Sheet Detail1
A1: Details for Count of Property Name - GoLiveDate: 10/14/2025, New Opening: N, Iteration: 1 - BETA 1 (1) (+)
A3: Iteration | B3: PropertyCode | C3: TenantId | D3: TenantCode | E3: PropertyId | F3: Region | G3: Property Name | H3: GoLiveDate | I3: New Opening
A4: 1 - BETA 1 (1) | B4: MCOWS | C4: 100033 | D4: MCOWS | E4: 60 | F4: US_EAST_1 | G4: SpringHill Suites by Marriott Winter Park | H4: 45944 | I4: N

Sheet Summary
V1: Iteration | W1: (Multiple Items) | Y1: New Opening | Z1: (Multiple Items)
A2: GoLiveDate | B2: (Multiple Items) | R2: New Opening | S2: (Multiple Items) | V2: New Opening | W2: (Multiple Items) | Y2: Iteration | Z2: (Multiple Items)
R3: Iteration | S3: (Multiple Items)
A4: Count of Property Name | B4: Column Labels | V4: Row Labels | W4: Sum of Room Count | Y4: Count of Property Name | Z4: Column Labels
A5: Row Labels | B5: US_EAST_1 | C5: US_WEST3_1 | D5: (blank) | E5: US_EAST_2 | F5: US_EAST_4 | G5: US_WEST3_2 | H5: US_WEST3_4 | I5: US_EAST_5 | J5: US_WEST3_5 | K5: US_EAST_6 | L5: US_EAST_7 | M5: US_WEST3_6 | N5: US_EAST_8 | O5: Grand Total | R5: Row Labels | S5: Count of Property Name | V5: 45944 | W5: 126 | Y5: Row Labels | Z5: US_EAST_1 | AA5: US_EAST_2 | AB5: US_EAST_4 | AC5: US_EAST_5 | AD5: US_EAST_6 | AE5: US_EAST_7 | AF5: US_EAST_8 | AG5: US_WEST3_1 | AH5: US_WEST3_2 | AI5: US_WEST3_4 | AJ5: US_WEST3_5 | AK5: US_WEST3_6 | AL5: (blank) | AM5: Grand Total
A6: 1 - BETA 1 (1) | B6: 1 | O6: 1 | R6: 45944 | S6: 1 | V6: 45958 | W6: 541 | Y6: 45944 | Z6: 1 | AM6: 1
A7: 11 - Wave 9 (3) | E7: 3 | O7: 3 | R7: 45958 | S7: 4 | V7: 46000 | W7: 2253 | Y7: 45958 | Z7: 4 | AM7: 4
A8: 2 - BETA 2 (4) | B8: 4 | O8: 4 | R8: 46000 | S8: 20 | V8: 46042 | W8: 5399 | Y8: 46000 | Z8: 12 | AG8: 8 | AM8: 20
A9: 3 - PILOT (20) | B9: 12 | C9: 8 | O9: 20 | R9: 46042 | S9: 50 | V9: 46070 | W9: 8066 | Y9: 46042 | Z9: 31 | AG9: 19 | AM9: 50
A10: 4 - WAVE 1 (50) | B10: 31 | C10: 19 | O10: 50 | R10: 46070 | S10: 75 | V10: 46084 | W10: 11233 | Y10: 46070 | Z10: 68 | AG10: 7 | AM10: 75
A11: 5 - Wave 4 (75) | B11: 68 | C11: 7 | O11: 75 | R11: 46084 | S11: 99 | V11: 46098 | W11: 10457 | Y11: 46084 | Z11: 83 | AG11: 16 | AM11: 99
A12: 6 - Wave 40 (99) | B12: 83 | C12: 16 | O12: 99 | R12: 46098 | S12: 99 | V12: 46119 | W12: 25972 | Y12: 46098 | Z12: 85 | AG12: 14 | AM12: 99
A13: 7 - Wave 5 (99) | B13: 85 | C13: 14 | O13: 99 | R13: 46119 | S13: 231 | V13: 46126 | W13: 92 | Y13: 46119 | Z13: 153 | AG13: 78 | AM13: 231
A14: 8 - Wave 6 (231) | B14: 153 | C14: 78 | O14: 231 | R14: 46126 | S14: 1 | V14: 46128 | W14: 79 | Y14: 46126 | Z14: 1 | AM14: 1
A15: 9 - Wave 7 (248) | B15: 15 | C15: 233 | O15: 248 | R15: 46128 | S15: 1 | V15: 46133 | W15: 27790 | Y15: 46128 | AG15: 1 | AM15: 1
A16: New Opening | B16: 9 | C16: 5 | D16: 2 | O16: 16 | R16: 46133 | S16: 248 | V16: 46147 | W16: 27097 | Y16: 46133 | Z16: 15 | AG16: 233 | AM16: 248
A17: NA | E17: 1 | O17: 1 | R17: 46147 | S17: 245 | V17: 46154 | W17: 477 | Y17: 46147 | AA17: 180 | AG17: 65 | AM17: 245
A18: 12 - Wave 10 (254) | F18: 93 | G18: 161 | O18: 254 | R18: 46154 | S18: 4 | V18: 46156 | W18: #N/A | Y18: 46154 | Z18: 1 | AA18: 3 | AM18: 4
A19: 13- Wave 11 (169) | H19: 22 | I19: 147 | O19: 169 | R19: 46156 | S19: 1 | V19: 46161 | W19: #N/A | Y19: 46156 | AG19: 1 | AM19: 1
A20: 14 - Wave 12 (22) | H20: 9 | I20: 13 | O20: 22 | R20: 46161 | S20: 255 | V20: 46170 | W20: #N/A | Y20: 46161 | Z20: 1 | AB20: 93 | AH20: 161 | AM20: 255
A21: 15 - Wave 13 (171) | J21: 110 | K21: 61 | O21: 171 | R21: 46170 | S21: 1 | V21: 46175 | W21: 17851 | Y21: 46170 | Z21: 1 | AM21: 1
A22: 16 - Wave 14 (171) | L22: 48 | M22: 123 | O22: 171 | R22: 46175 | S22: 169 | V22: 46176 | W22: #N/A | Y22: 46175 | AC22: 147 | AI22: 22 | AM22: 169
A23: 17 - Wave 15 (170) | M23: 61 | N23: 109 | O23: 170 | R23: 46176 | S23: 1 | V23: 46182 | W23: 2814 | Y23: 46176 | Z23: 1 | AM23: 1
A24: 10 - Wave 8 (245) | C24: 65 | E24: 180 | O24: 245 | R24: 46182 | S24: 22 | V24: 46189 | W24: 19701 | Y24: 46182 | AC24: 13 | AI24: 9 | AM24: 22
A25: Grand Total | B25: 461 | C25: 445 | D25: 2 | E25: 184 | F25: 93 | G25: 161 | H25: 31 | I25: 160 | J25: 110 | K25: 61 | L25: 48 | M25: 184 | N25: 109 | O25: 2049 | R25: 46189 | S25: 171 | V25: 46191 | W25: #N/A | Y25: 46189 | AD25: 61 | AJ25: 110 | AM25: 171
R26: 46191 | S26: 1 | V26: 46196 | W26: #N/A | Y26: 46191 | AG26: 1 | AM26: 1
R27: 46196 | S27: 1 | V27: 46198 | W27: #N/A | Y27: 46196 | Z27: 1 | AM27: 1
R28: 46198 | S28: 1 | V28: 46203 | W28: #N/A | Y28: 46198 | AG28: 1 | AM28: 1
R29: 46203 | S29: 1 | V29: 46210 | W29: #N/A | Y29: 46203 | Z29: 1 | AM29: 1
R30: 46210 | S30: 171 | V30: 46224 | W30: #N/A | Y30: 46210 | AE30: 48 | AK30: 123 | AM30: 171
R31: 46224 | S31: 170 | V31: 46237 | W31: #N/A | Y31: 46224 | AF31: 109 | AK31: 61 | AM31: 170
R32: 46237 | S32: 1 | V32: 46240 | W32: #N/A | Y32: 46237 | Z32: 1 | AM32: 1
R33: 46240 | S33: 1 | V33: 46253 | W33: #N/A | Y33: 46240 | AG33: 1 | AM33: 1
R34: 46253 | S34: 1 | V34: 46261 | W34: #N/A | Y34: 46253 | AL34: 1 | AM34: 1
R35: 46261 | S35: 1 | V35: 46541 | W35: #N/A | Y35: 46261 | Z35: 1 | AM35: 1
R36: 46541 | S36: 1 | V36: Grand Total | W36: #N/A | Y36: 46541 | AL36: 1 | AM36: 1
R37: Grand Total | S37: 2048 | Y37: Grand Total | Z37: 461 | AA37: 183 | AB37: 93 | AC37: 160 | AD37: 61 | AE37: 48 | AF37: 109 | AG37: 445 | AH37: 161 | AI37: 31 | AJ37: 110 | AK37: 184 | AL37: 2 | AM37: 2048

Sheet PropertyList
A1: Iteration | B1: PropertyCode | C1: TenantId | D1: TenantCode | E1: PropertyId | F1: Region | G1: Property Name | H1: GoLiveDate | I1: New Opening | J1: Room Count | K1: Search By TenantId /Property Id/Property Code
A2: 2 - BETA 2 (4) | B2: PITSS | C2: 100027 | D2: PITSS | E2: 57 | F2: US_EAST_1 | G2: =VLOOKUP(B2,'Property Name List'!A$2:D$834,3,FALSE) -> SpringHill Suites By Marriott Pittsburgh Southside Works | H2: 45958 | I2: N | J2: =VLOOKUP(E2,'Room Count'!A$2:B$2616,2,FALSE) -> 115 | K2: DTWSF
A3: 2 - BETA 2 (4) | B3: CAESH | C3: 100029 | D3: CAESH | E3: 58 | F3: US_EAST_1 | G3: =VLOOKUP(B3,'Property Name List'!A$2:D$834,3,FALSE) -> SpringHill Suites By Marriott Columbia Downtown/The Vista | H3: 45958 | I3: N | J3: =VLOOKUP(E3,'Room Count'!A$2:B$2616,2,FALSE) -> 132 | L3: Search Result
A4: 2 - BETA 2 (4) | B4: BWISL | C4: 100031 | D4: BWISL | E4: 59 | F4: US_EAST_1 | G4: =VLOOKUP(B4,'Property Name List'!A$2:D$834,3,FALSE) -> SpringHill Suites by Marriott Baltimore Downtown Convention Center Area | H4: 45958 | I4: N | J4: =VLOOKUP(E4,'Room Count'!A$2:B$2616,2,FALSE) -> 157 | K4: TenantId | L4: =_xlfn.XLOOKUP( K2, PropertyList!C:C, PropertyList!E:E, _xlfn.XLOOKUP(K2,PropertyList!C:C,PropertyList!C:C, _xlfn.XLOOKUP(K2,PropertyList!B:B,PropertyList!C:C,"Not Found")) ) -> 100537
A5: 1 - BETA 1 (1) | B5: MCOWS | C5: 100033 | D5: MCOWS | E5: 60 | F5: US_EAST_1 | G5: =VLOOKUP(B5,'Property Name List'!A$2:D$834,3,FALSE) -> SpringHill Suites by Marriott Winter Park | H5: 45944 | I5: N | J5: =VLOOKUP(E5,'Room Count'!A$2:B$2616,2,FALSE) -> 126 | K5: PropertyId | L5: =_xlfn.XLOOKUP( K2, PropertyList!C:C, PropertyList!E:E, _xlfn.XLOOKUP(K2,PropertyList!E:E,PropertyList!E:E, _xlfn.XLOOKUP(K2,PropertyList!B:B,PropertyList!E:E,"Not Found")) ) -> 394
A6: 2 - BETA 2 (4) | B6: CHIFO | C6: 100035 | D6: CHIFO | E6: 61 | F6: US_EAST_1 | G6: =VLOOKUP(B6,'Property Name List'!A$2:D$834,3,FALSE) -> Fairfield by Marriott Inn & Suites Chicago O'Hare | H6: 45958 | I6: N | J6: =VLOOKUP(E6,'Room Count'!A$2:B$2616,2,FALSE) -> 137 | K6: Property Code | L6: =_xlfn.XLOOKUP( K2, PropertyList!C:C, PropertyList!B:B, _xlfn.XLOOKUP( K2, PropertyList!E:E, PropertyList!B:B, _xlfn.XLOOKUP( K2, PropertyList!B:B, PropertyList!B:B, "Not Found" ) ) ) -> DTWSF
A7: 3 - PILOT (20) | B7: ALBTY | C7: 100037 | D7: ALBTY | E7: 71 | F7: US_EAST_1 | G7: =VLOOKUP(B7,'Property Name List'!A$2:D$834,3,FALSE) -> Courtyard By Marriott Albany Troy/Waterfront | H7: 46000 | I7: N | J7: =VLOOKUP(E7,'Room Count'!A$2:B$2616,2,FALSE) -> 132 | K7: Region | L7: =_xlfn.XLOOKUP( L4, PropertyList!C:C, PropertyList!F:F ) -> US_EAST_1
A8: 4 - WAVE 1 (50) | B8: BISCN | C8: 100039 | D8: BISCN | E8: 72 | F8: US_EAST_1 | G8: =VLOOKUP(B8,'Property Name List'!A$2:D$834,3,FALSE) -> Courtyard By Marriott Bismarck North | H8: 46042 | I8: N | J8: =VLOOKUP(E8,'Room Count'!A$2:B$2616,2,FALSE) -> 89 | K8: Property Name | L8: =_xlfn.XLOOKUP( L4, PropertyList!C:C, PropertyList!G:G ) -> Courtyard By Marriott Detroit Southfield
A9: 3 - PILOT (20) | B9: MSPOX | C9: 100041 | D9: MSPOX | E9: 75 | F9: US_EAST_1 | G9: =VLOOKUP(B9,'Property Name List'!A$2:D$834,3,FALSE) -> Moxy Minneapolis Uptown | H9: 46000 | I9: N | J9: =VLOOKUP(E9,'Room Count'!A$2:B$2616,2,FALSE) -> 125 | K9: Go Live Date | L9: =_xlfn.XLOOKUP( L4, PropertyList!C:C, PropertyList!H:H ) -> 46133
A10: 3 - PILOT (20) | B10: BZNAR | C10: 100043 | D10: BZNAR | E10: 79 | F10: US_EAST_1 | G10: =VLOOKUP(B10,'Property Name List'!A$2:D$834,3,FALSE) -> AC Hotel Bozeman Downtown | H10: 46000 | I10: N | J10: =VLOOKUP(E10,'Room Count'!A$2:B$2616,2,FALSE) -> 143 | K10: Wave | L10: =_xlfn.XLOOKUP( L4, PropertyList!C:C, PropertyList!A:A ) -> 9 - Wave 7 (248)
A11: 4 - WAVE 1 (50) | B11: YYZAP | C11: 100045 | D11: YYZAP | E11: 88 | F11: US_EAST_1 | G11: =VLOOKUP(B11,'Property Name List'!A$2:D$834,3,FALSE) -> Courtyard By Marriott Toronto Airport | H11: 46042 | I11: N | J11: =VLOOKUP(E11,'Room Count'!A$2:B$2616,2,FALSE) -> 168
A12: 3 - PILOT (20) | B12: YYBFI | C12: 100047 | D12: YYBFI | E12: 89 | F12: US_EAST_1 | G12: =VLOOKUP(B12,'Property Name List'!A$2:D$834,3,FALSE) -> Fairfield by Marriott Inn & Suites North Bay | H12: 46000 | I12: N | J12: =VLOOKUP(E12,'Room Count'!A$2:B$2616,2,FALSE) -> 92
A13: 4 - WAVE 1 (50) | B13: YSBFI | C13: 100049 | D13: YSBFI | E13: 90 | F13: US_EAST_1 | G13: =VLOOKUP(B13,'Property Name List'!A$2:D$834,3,FALSE) -> Fairfield Inn & Suites Sudbury | H13: 46042 | I13: N | J13: =VLOOKUP(E13,'Room Count'!A$2:B$2616,2,FALSE) -> 81
A14: 4 - WAVE 1 (50) | B14: WASAX | C14: 100051 | D14: WASAX | E14: 92 | F14: US_EAST_1 | G14: =VLOOKUP(B14,'Property Name List'!A$2:D$834,3,FALSE) -> SpringHill Suites By Marriott Alexandria | H14: 46042 | I14: N | J14: =VLOOKUP(E14,'Room Count'!A$2:B$2616,2,FALSE) -> 91
A15: 3 - PILOT (20) | B15: TPAPC | C15: 100053 | D15: TPAPC | E15: 93 | F15: US_EAST_1 | G15: =VLOOKUP(B15,'Property Name List'!A$2:D$834,3,FALSE) -> Fairfield Inn & Suites Lakeland Plant City | H15: 46000 | I15: N | J15: =VLOOKUP(E15,'Room Count'!A$2:B$2616,2,FALSE) -> 87
A16: 4 - WAVE 1 (50) | B16: TIXFI | C16: 100055 | D16: TIXFI | E16: 94 | F16: US_EAST_1 | G16: =VLOOKUP(B16,'Property Name List'!A$2:D$834,3,FALSE) -> Fairfield Inn & Suites Titusville Kennedy Space Center | H16: 46042 | I16: N | J16: =VLOOKUP(E16,'Room Count'!A$2:B$2616,2,FALSE) -> 96
A17: 3 - PILOT (20) | B17: RQSFO | C17: 100057 | D17: RQSFO | E17: 95 | F17: US_EAST_1 | G17: =VLOOKUP(B17,'Property Name List'!A$2:D$834,3,FALSE) -> Fairfield by Marriott Inn & Suites Orillia | H17: 46000 | I17: N | J17: =VLOOKUP(E17,'Room Count'!A$2:B$2616,2,FALSE) -> 92
A18: 3 - PILOT (20) | B18: INDCU | C18: 100059 | D18: INDCU | E18: 97 | F18: US_EAST_1 | G18: =VLOOKUP(B18,'Property Name List'!A$2:D$834,3,FALSE) -> Courtyard By Marriott Indianapolis Plainfield | H18: 46000 | I18: N | J18: =VLOOKUP(E18,'Room Count'!A$2:B$2616,2,FALSE) -> 117
A19: 4 - WAVE 1 (50) | B19: IAGCY | C19: 100061 | D19: IAGCY | E19: 98 | F19: US_EAST_1 | G19: =VLOOKUP(B19,'Property Name List'!A$2:D$834,3,FALSE) -> Courtyard By Marriott Niagara Falls | H19: 46042 | I19: N | J19: =VLOOKUP(E19,'Room Count'!A$2:B$2616,2,FALSE) -> 254
A20: 4 - WAVE 1 (50) | B20: FLOCS | C20: 100063 | D20: FLOCS | E20: 99 | F20: US_EAST_1 | G20: =VLOOKUP(B20,'Property Name List'!A$2:D$834,3,FALSE) -> SpringHill Suites By Marriott Cheraw | H20: 46042 | I20: N | J20: =VLOOKUP(E20,'Room Count'!A$2:B$2616,2,FALSE) -> 102
A21: 4 - WAVE 1 (50) | B21: CVGMT | C21: 100065 | D21: CVGMT | E21: 101 | F21: US_EAST_1 | G21: =VLOOKUP(B21,'Property Name List'!A$2:D$834,3,FALSE) -> Fairfield Inn & Suites Cincinnati Uptown/University Area | H21: 46042 | I21: N | J21: =VLOOKUP(E21,'Room Count'!A$2:B$2616,2,FALSE) -> 115
A22: 3 - PILOT (20) | B22: AHNSH | C22: 100067 | D22: AHNSH | E22: 102 | F22: US_EAST_1 | G22: =VLOOKUP(B22,'Property Name List'!A$2:D$834,3,FALSE) -> SpringHill Suites By Marriott Athens West | H22: 46000 | I22: N | J22: =VLOOKUP(E22,'Room Count'!A$2:B$2616,2,FALSE) -> 99
... A38: 6 - Wave 40 (99) | B38: AIDFI | C38: 100099 | D38: AIDFI | E38: 137 | F38: US_EAST_1 | G38: =VLOOKUP(B38,'Property Name List'!A$2:D$834,3,FALSE) -> Fairfield Inn & Suites Anderson | H38: 46084 | I38: N | J38: =VLOOKUP(E38,'Room Count'!A$2:B$2616,2,FALSE) -> 85
A39: 6 - Wave 40 (99) | B39: AHNSE | C39: 100101 | D39: AHNSE | E39: 138 | F39: US_EAST_1 | G39: =VLOOKUP(B39,'Property Name List'!A$2:D$834,3,FALSE) -> SpringHill Suites By Marriott Athens Downtown/University Area | H39: 46084 | I39: N | J39: =VLOOKUP(E39,'Room Count'!A$2:B$2616,2,FALSE) -> 200
A40: 4 - WAVE 1 (50) | B40: EWBFS | C40: 100103 | D40: EWBFS | E40: 139 | F40: US_EAST_1 | G40: =VLOOKUP(B40,'Property Name List'!A$2:D$834,3,FALSE) -> Fairfield Inn & Suites Somerset | H40: 46042 | I40: N | J40: =VLOOKUP(E40,'Room Count'!A$2:B$2616,2,FALSE) -> 111
A41: 6 - Wave 40 (99) | B41: DABPC | C41: 100105 | D41: DABPC | E41: 140 | F41: US_EAST_1 | G41: =VLOOKUP(B41,'Property Name List'!A$2:D$834,3,FALSE) -> Fairfield Inn & Suites Palm Coast I-95 | H41: 46084 | I41: N | J41: =VLOOKUP(E41,'Room Count'!A$2:B$2616,2,FALSE) -> 108
A42: 4 - WAVE 1 (50) | B42: PITFM | C42: 100107 | D42: PITFM | E42: 141 | F42: US_EAST_1 | G42: =VLOOKUP(B42,'Property Name List'!A$2:D$834,3,FALSE) -> Fairfield Inn & Suites Pittsburgh North/McCandless Crossing | H42: 46042 | I42: N | J42: =VLOOKUP(E42,'Room Count'!A$2:B$2616,2,FALSE) -> 109
A43: 6 - Wave 40 (99) | B43: CHAOW | C43: 100109 | D43: CHAOW | E43: 142 | F43: US_EAST_1 | G43: =VLOOKUP(B43,'Property Name List'!A$2:D$834,3,FALSE) -> SpringHill Suites By Marriott Chattanooga North/Ooltewah | H43: 46084 | I43: N | J43: =VLOOKUP(E43,'Room Count'!A$2:B$2616,2,FALSE) -> 106
A44: 6 - Wave 40 (99) | B44: ABYAB | C44: 100111 | D44: ABYAB | E44: 143 | F44: US_EAST_1 | G44: =VLOOKUP(B44,'Property Name List'!A$2:D$834,3,FALSE) -> Fairfield Inn & Suites Albany | H44: 46084 | I44: N | J44: =VLOOKUP(E44,'Room Count'!A$2:B$2616,2,FALSE) -> 87
A45: 6 - Wave 40 (99) | B45: BMGSH | C45: 100113 | D45: BMGSH | E45: 144 | F45: US_EAST_1 | G45: =VLOOKUP(B45,'Property Name List'!A$2:D$834,3,FALSE) -> SpringHill Suites By Marriott Bloomington | H45: 46084 | I45: N | J45: =VLOOKUP(E45,'Room Count'!A$2:B$2616,2,FALSE) -> 158
A46: 6 - Wave 40 (99) | B46: AHNGV | C46: 100115 | D46: AHNGV | E46: 145 | F46: US_EAST_1 | G46: =VLOOKUP(B46,'Property Name List'!A$2:D$834,3,FALSE) -> Fairfield Inn & Suites Gainesville | H46: 46084 | I46: N | J46: =VLOOKUP(E46,'Room Count'!A$2:B$2616,2,FALSE) -> 75
A47: 6 - Wave 40 (99) | B47: CHSCS | C47: 100117 | D47: CHSCS | E47: 146 | F47: US_EAST_1 | G47: =VLOOKUP(B47,'Property Name List'!A$2:D$834,3,FALSE) -> Fairfield Inn & Suites Charleston Airport/Convention Center | H47: 46084 | I47: N | J47: =VLOOKUP(E47,'Room Count'!A$2:B$2616,2,FALSE) -> 102
A48: 4 - WAVE 1 (50) | B48: ORFOC | C48: 100119 | D48: ORFOC | E48: 147 | F48: US_EAST_1 | G48: =VLOOKUP(B48,'Property Name List'!A$2:D$834,3,FALSE) -> Courtyard By Marriott Virginia Beach Oceanfront/South | H48: 46042 | I48: N | J48: =VLOOKUP(E48,'Room Count'!A$2:B$2616,2,FALSE) -> 141
A49: 6 - Wave 40 (99) | B49: CLECA | C49: 100121 | D49: CLECA | E49: 148 | F49: US_EAST_1 | G49: =VLOOKUP(B49,'Property Name List'!A$2:D$834,3,FALSE) -> Courtyard By Marriott Cleveland Airport South | H49: 46084 | I49: N | J49: =VLOOKUP(E49,'Room Count'!A$2:B$2616,2,FALSE) -> 153
A50: 6 - Wave 40 (99) | B50: AOOFI | C50: 100123 | D50: AOOFI | E50: 149 | F50: US_EAST_1 | G50: =VLOOKUP(B50,'Property Name List'!A$2:D$834,3,FALSE) -> Fairfield Inn & Suites Bedford | H50: 46084 | I50: N | J50: =VLOOKUP(E50,'Room Count'!A$2:B$2616,2,FALSE) -> 84
A51: 4 - WAVE 1 (50) | B51: IPTFL | C51: 100125 | D51: IPTFL | E51: 150 | F51: US_EAST_1 | G51: =VLOOKUP(B51,'Property Name List'!A$2:D$834,3,FALSE) -> Fairfield Inn & Suites Lewisburg | H51: 46042 | I51: N | J51: =VLOOKUP(E51,'Room Count'!A$2:B$2616,2,FALSE) -> 107
... A128: 5 - Wave 4 (75) | B128: TPACR | C128: 100279 | D128: TPACR | E128: 252 | F128: US_EAST_1 | G128: =VLOOKUP(B128,'Property Name List'!A$2:D$834,3,FALSE) -> Fairfield Inn & Suites Clearwater | H128: 46070 | I128: N | J128: =VLOOKUP(E128,'Room Count'!A$2:B$2616,2,FALSE) -> 127
A129: NA | B129: HHHBS | C129: 100281 | D129: HHHBS | E129: 253 | F129: US_EAST_1 | G129: =VLOOKUP(B129,'Property Name List'!A$2:D$834,3,FALSE) -> SpringHill Suites by Marriott Beaufort | H129: NA | I129: N | J129: =VLOOKUP(E129,'Room Count'!A$2:B$2616,2,FALSE) -> 111
A130: 5 - Wave 4 (75) | B130: ROCCD | C130: 100283 | D130: ROCCD | E130: 254 | F130: US_EAST_1 | G130: =VLOOKUP(B130,'Property Name List'!A$2:D$834,3,FALSE) -> Courtyard By Marriott Rochester Downtown | H130: 46070 | I130: N | J130: =VLOOKUP(E130,'Room Count'!A$2:B$2616,2,FALSE) -> 126
A131: 6 - Wave 40 (99) | B131: HARCA | C131: 100285 | D131: HARCA | E131: 255 | F131: US_EAST_1 | G131: =VLOOKUP(B131,'Property Name List'!A$2:D$834,3,FALSE) -> Courtyard By Marriott Hershey Chocolate Avenue | H131: 46084 | I131: N | J131: =VLOOKUP(E131,'Room Count'!A$2:B$2616,2,FALSE) -> 120
...

Sheet Sheet2
A1: HSVDF | D1: HSVDF | F1: FAYLB | G1: FAYLB | J1: 769 | K1: Fairfield Inn & Suites Athens
A2: CHIOX | D2: CHIOX | F2: DBNFI | G2: DBNFI | J2: 873 | K2: SpringHill Suites By Marriott Dallas Lewisville
A3: DFWCA | D3: DFWCA | F3: EWNCY | G3: EWNCY | J3: 762 | K3: SpringHill Suites By Marriott Devens Common Center
A4: FSDNW | D4: FSDNW | F4: EYWFI | G4: EYWFI | J4: 716 | K4: Fairfield by Marriott Inn & Suites Columbus Hilliard
A5: ICTFE | D5: ICTFE | F5: DTWFL | G5: DTWFL | J5: 706 | K5: Courtyard By Marriott Lenox Berkshires
A6: GPTSH | D6: GPTSH | F6: DTWSF | G6: DTWSF | J6: 864 | K6: Fairfield Inn & Suites Snyder
A7: BHMTV | D7: BHMTV | F7: DXRCY | G7: DXRCY | J7: 910 | K7: Courtyard By Marriott Los Angeles Century City/Beverly Hills
A8: FOESH | D8: FOESH | F8: DAYUD | G8: DAYUD | J8: 785 | K8: Fairfield Inn By Marriott Charlotte Northlake
A9: LAWFI | D9: LAWFI | F9: DTWFH | G9: DTWFH | J9: 862 | K9: SpringHill Suites By Marriott Austin South
A10: GTRSV | D10: GTRSV | F10: DTWMB | G10: DTWMB | J10: 783 | K10: Fairfield Inn & Suites Anderson Clemson
A11: MHTDT | D11: MHTDT | F11: FAYDN | G11: FAYDN | J11: 689 | K11: SpringHill Suites by Marriott Lexington Fritz Farm
A12: ITHFC | D12: ITHFC | F12: EVVFW | G12: EVVFW | J12: 787 | K12: Courtyard By Marriott Charlotte Matthews
... A231: FAYRH | D231: CHAOX | F231: JAXAP | G231: GSOSH | J231: 688 | K231: SpringHill Suites By Marriott Richmond Northwest
A232: CHAOX | F232: GSOSH | G232: EWRFI | J232: 848 | K232: Courtyard By Marriott Salina
F233: EWRFI | G233: NYCFF
F234: NYCFF | G234: GNVSH
F235: GNVSH | G235: PHLFA
F236: PHLFA | G236: AGSAF
F237: AGSAF | G237: WASUS
F238: WASUS | G238: YYZMS
F239: YYZMS | G239: ELMCH
F240: ELMCH | G240: IAGIF
F241: IAGIF | G241: YAMFI
F242: YAMFI | G242: MCNMD
F243: MCNMD | G243: MHTCN
F244: MHTCN | G244: TPAYC
... F249: ILMCY | G249: PITGB
F250: PITGB

Sheet Sheet1
A1: 100425
A2: 200113 | D2: SMFDA | E2: SMFDA | F2: 200899 | G2: 1623 | H2: Aloft El Dorado Hills
A3: 200111 | D3: ABQLF | E3: ABQLF | F3: 200903 | G3: 1654 | H3: Fairfield by Marriott Inn & Suites Los Lunas
A4: 100413 | D4: DENNC | E4: DENNC | F4: 200897 | G4: 1621 | H4: AC Hotel Denver RiNo
A5: 200109 | D5: DALMN | E5: DALMN | F5: 200905 | G5: 1655 | H5: AC Hotel McKinney
A6: 100399 | D6: LNKYF | E6: LNKYF | F6: 200901 | G6: 1653 | H6: Fairfield by Marriott Inn & Suites York
A7: 100393 | D7: INDLF | E7: INDLF | F7: 100973 | G7: 1831 | H7: Fairfield by Marriott Inn & Suites Lebanon
A8: 200099 | D8: DAYFS | E8: DAYFS | F8: 100961 | G8: 1649 | H8: Fairfield by Marriott Inn & Suites Sidney
A9: 200095 | D9: YOWOX | E9: YOWOX | F9: 100963 | G9: 1650 | H9: Moxy Ottawa Downtown
A10: 100375 | D10: BOSSF | E10: BOSSF | F10: 100955 | G10: 1624 | H10: Fairfield by Marriott Inn & Suites Stoughton
A11: 100441 | D11: CLESU | E11: CLESU | F11: 100957 | G11: 1625 | H11: SpringHill Suites by Marriott Sandusky
A12: 100479 | D12: YYZBF | E12: YYZBF | F12: 100975 | G12: 1835 | H12: Fairfield by Marriott Inn & Suites Bradford
A13: 100485 | D13: ATLMO | E13: ATLMO | F13: 100959 | G13: 1648 | H13: Fairfield by Marriott Inn & Suites Morrow
... A15: 100509 | D15: DTWSH | E15: DTWSH | F15: 100965 | G15: 1651 | H15: Fairfield by Marriott Inn & Suites Detroit Sterling Heights
A16: 100521
A17: 100533
A18: 100541
A19: 100545
A20: 100555
A21: 100557
A22: 100577
A23: 100585
A24: 100591
A25: 100625
A26: 100645
A27: 100647
... A232: 100695

Sheet Sheet3
A1: 12 - Wave 10 (254) | B1: =_xlfn.XLOOKUP(D1,O:O,Q:Q,"Not Found") -> NYCQJ | C1: 111001 | D1: NYCQJ | E1: 1181 | F1: US_EAST_4 | G1: =_xlfn.XLOOKUP(D1,O:O,P:P,"Not Found") -> Courtyard by Marriott New York Queens/Jamaica | H1: 46161 | O1: ABQFA | P1: Fairfield by Marriott Inn & Suites Albuquerque Airport | Q1: ABQFA
A2: 12 - Wave 10 (254) | B2: =_xlfn.XLOOKUP(D2,O:O,Q:Q,"Not Found") -> NYCFJ | C2: 111001 | D2: NYCFJ | E2: 1185 | F2: US_EAST_4 | G2: =_xlfn.XLOOKUP(D2,O:O,P:P,"Not Found") -> Fairfield by Marriott Inn & Suites New York Queens/Jamaica | H2: 46161 | O2: ABQFN | P2: Fairfield by Marriott Inn & Suites Albuquerque North | Q2: ABQFN
A3: 12 - Wave 10 (254) | B3: =_xlfn.XLOOKUP(D3,O:O,Q:Q,"Not Found") -> PRHFI | C3: 111003 | D3: PRHFI | E3: 1182 | F3: US_EAST_4 | G3: =_xlfn.XLOOKUP(D3,O:O,P:P,"Not Found") -> Fairfield Inn Port Huron | H3: 46161 | O3: ALSFI | P3: Fairfield by Marriott Inn & Suites Alamosa | Q3: ALSFI
A4: 12 - Wave 10 (254) | B4: =_xlfn.XLOOKUP(D4,O:O,Q:Q,"Not Found") -> NYCTM | C4: 111005 | D4: NYCTM | E4: 1183 | F4: US_EAST_4 | G4: =_xlfn.XLOOKUP(D4,O:O,P:P,"Not Found") -> Fairfield by Marriott Inn & Suites New York Manhattan/Fifth Avenue | H4: 46161 | O4: ATLCN | P4: AC Hotel Atlanta Midtown | Q4: ATLCN
A5: 12 - Wave 10 (254) | B5: =_xlfn.XLOOKUP(D5,O:O,Q:Q,"Not Found") -> HPNNB | C5: 111007 | D5: HPNNB | E5: 1184 | F5: US_EAST_4 | G5: =_xlfn.XLOOKUP(D5,O:O,P:P,"Not Found") -> Courtyard by Marriott Newburgh Stewart Airport | H5: 46161 | O5: ATLDU | P5: Courtyard by Marriott Atlanta NE/Duluth Sugarloaf | Q5: ATLDU
A6: 12 - Wave 10 (254) | B6: =_xlfn.XLOOKUP(D6,O:O,Q:Q,"Not Found") -> PWMCD | C6: 111009 | D6: PWMCD | E6: 1186 | F6: US_EAST_4 | G6: =_xlfn.XLOOKUP(D6,O:O,P:P,"Not Found") -> Courtyard by Marriott Portland Downtown/Waterfront | H6: 46161 | O6: ATLKE | P6: Courtyard by Marriott Atlanta Kennesaw | Q6: ATLKE
A7: 12 - Wave 10 (254) | B7: =_xlfn.XLOOKUP(D7,O:O,Q:Q,"Not Found") -> EWRPX | C7: 111011 | D7: EWRPX | E7: 1187 | F7: US_EAST_4 | G7: =_xlfn.XLOOKUP(D7,O:O,P:P,"Not Found") -> Fairfield by Marriott Inn & Suites Paramus | H7: 46161 | O7: ATLOX | P7: Moxy Atlanta Midtown | Q7: ATLOX
A8: 12 - Wave 10 (254) | B8: =_xlfn.XLOOKUP(D8,O:O,Q:Q,"Not Found") -> EWRWK | C8: 111013 | D8: EWRWK | E8: 1188 | F8: US_EAST_4 | G8: =_xlfn.XLOOKUP(D8,O:O,P:P,"Not Found") -> Courtyard by Marriott North Brunswick | H8: 46161 | O8: ATLSD | P8: SpringHill Suites by Marriott Atlanta Downtown | Q8: ATLSD
A9: 12 - Wave 10 (254) | B9: =_xlfn.XLOOKUP(D9,O:O,Q:Q,"Not Found") -> PHLRO | C9: 111015 | D9: PHLRO | E9: 1190 | F9: US_EAST_4 | G9: =_xlfn.XLOOKUP(D9,O:O,P:P,"Not Found") -> Fairfield by Marriott Inn & Suites Philadelphia Broomall/Newtown Square | H9: 46161 | O9: ATLSG | P9: SpringHill Suites by Marriott Atlanta Northwest | Q9: ATLSG
A10: 12 - Wave 10 (254) | B10: =_xlfn.XLOOKUP(D10,O:O,Q:Q,"Not Found") -> PBIFF | C10: 111017 | D10: PBIFF | E10: 1191 | F10: US_EAST_4 | G10: =_xlfn.XLOOKUP(D10,O:O,P:P,"Not Found") -> Fairfield by Marriott Inn & Suites Palm Beach | H10: 46161 | O10: ATLSS | P10: SpringHill Suites by Marriott Atlanta Alpharetta | Q10: ATLSS
A11: 12 - Wave 10 (254) | B11: =_xlfn.XLOOKUP(D11,O:O,Q:Q,"Not Found") -> PITDF | C11: 111019 | D11: PITDF | E11: 1192 | F11: US_EAST_4 | G11: =_xlfn.XLOOKUP(D11,O:O,P:P,"Not Found") -> Fairfield by Marriott Inn & Suites Pittsburgh Downtown | H11: 46161 | O11: ATLVG | P11: Courtyard by Marriott Atlanta Vinings/Galleria | Q11: ATLVG
A12: 12 - Wave 10 (254) | B12: =_xlfn.XLOOKUP(D12,O:O,Q:Q,"Not Found") -> TYSKW | C12: 111021 | D12: TYSKW | E12: 1193 | F12: US_EAST_4 | G12: =_xlfn.XLOOKUP(D12,O:O,P:P,"Not Found") -> SpringHill Suites by Marriott Knoxville at Turkey Creek | H12: 46161 | O12: ATLYN | P12: Courtyard by Marriott Atlanta Dunwoody | Q12: ATLYN
... A254: 12 - Wave 10 (254) | B254: =_xlfn.XLOOKUP(D254,O:O,Q:Q,"Not Found") -> RNODT | C254: 210319 | D254: RNODT | E254: 1434 | F254: US_WEST3_2 | G254: =_xlfn.XLOOKUP(D254,O:O,P:P,"Not Found") -> Courtyard by Marriott Reno Downtown/Riverfront | H254: 46161 | O254: YYZTM | P254: Fairfield by Marriott Inn & Suites Toronto Mississauga | Q254: YYZTM

Sheet Comtrol Properties List
A1: Host Name | B1: Comtrol Version | C1: Property Code | D1: Property Version
A2: prod-26 | B2: 27200 | C2: - | D2: -
A3: prod-25 | B3: 26600 | C3: - | D3: -
A4: prod-24 | B4: 26600 | C4: - | D4: -
A5: prod-23 | B5: 26600 | C5: - | D5: -
A6: prod-22 | B6: 26600 | C6: - | D6: -
A7: prod-21 | B7: 26600 | C7: - | D7: -
A8: prod-20 | B8: 27200 | C8: EATML | D8: 27200
A9: prod-20 | B9: 27200 | C9: MFRFK | D9: 27200
A10: prod-20 | B10: 27200 | C10: PDXNH | D10: 27300
A11: prod-20 | B11: 27200 | C11: YRVFI | D11: 27200
A12: prod-20 | B12: 27200 | C12: YSNFI | D12: 27200
A13: prod-20 | B13: 27200 | C13: YVEFI | D13: 27200
A14: prod-20 | B14: 27200 | C14: YXSCY | D14: 27200
A15: prod-19 | B15: 26600 | C15: - | D15: -
A16: prod-18 | B16: 27200 | C16: BOICY | D16: 27300
A17: prod-18 | B17: 27200 | C17: BOIFW | D17: 27200
A18: prod-18 | B18: 27200 | C18: BZNAR | D18: 27200
A19: prod-18 | B19: 27200 | C19: CYSFI | D19: 27200
A20: prod-18 | B20: 27200 | C20: DENLF | D20: 27200
A21: prod-18 | B21: 27200 | C21: JACSH | D21: 27200
A22: prod-18 | B22: 27200 | C22: PHXMZ | D22: 27200
A23: prod-18 | B23: 27200 | C23: YQLFI | D23: 27200
A24: prod-17 | B24: 26600 | C24: - | D24: -
A25: prod-16 | B25: 26600 | C25: - | D25: -
A26: prod-15 | B26: 26600 | C26: - | D26: -
A27: prod-14 | B27: 26600 | C27: - | D27: -
A28: prod-13 | B28: 26600 | C28: - | D28: -
A29: prod-12 | B29: 26600 | C29: - | D29: -
A30: prod-11 | B30: 27200 | C30: AUSBU | D30: 27200
A31: prod-11 | B31: 27200 | C31: AUSCP | D31: 27300
A32: prod-11 | B32: 27200 | C32: AUSNL | D32: 27200
A33: prod-11 | B33: 27200 | C33: BISCN | D33: 27200
A34: prod-11 | B34: 27200 | C34: CHIFO | D34: 27200
A35: prod-11 | B35: 27200 | C35: DALSK | D35: 27200
A36: prod-11 | B36: 27200 | C36: DSMSA | D36: 27200
A37: prod-11 | B37: 27200 | C37: HOTFA | D37: 27200
A38: prod-11 | B38: 27200 | C38: LBFFI | D38: 27200
A39: prod-11 | B39: 27200 | C39: LITCR | D39: 27200
A40: prod-11 | B40: 27200 | C40: LITSH | D40: 27200
...

Sheet Exceptional Properties
A2: Property Code | B2: Tenant Id | C2: Property Id | H2: PILOT/BETA TENANTID LIST | I2: ['100037','100041','100043','100047','100053','100057','100059','100067','100069','100073','100075','100077','200009','200013','200015','200021','200033','200039','200041','200043','100031','100029','100035','100033','100027']
A3: 9865 | B3: 100005 | C3: 27
A4: 9876 | B4: 100005 | C4: 14
A5: 30024 | B5: 100003 | C5: 69
A6: 34765 | B6: 100005 | C6: 29
A7: 89113 | B7: 200007 | C7: 70 | H7: Wave 1 (19) - Westus | I7: ["200031","200017","200037","200029","200035","200011","200027","200023","200019","200025","200065","200067","200045","200047","200049","200051","200055","200075","200087"]
A8: ADM053 | B8: 100011 | C8: 38
A9: ADM81 | B9: 100025 | C9: 51 | H9: Wave 1 (31) - Eastus | I9: ["100039","100045","100049","100051","100055","100061","100063","100065","100071","100079","100081","100083","100085","100087","100091","100097","100103","100107","100119","100125","100127","100171","100129","100143","100147","100153","100157","100167","100175","100193","100195"]
A10: adm99 | B10: 100017 | C10: 46
A11: GOLDEN | B11: 100019 | C11: 48
A12: VPT | B12: 200005 | C12: 66
A13: AQACY | B13: 100017 | C13: 52
A14: AQACY | B14: 100021 | C14: 53
A15: MFMGT | B15: 100007 | C15: 68
A16: TEST | B16: 100001 | C16: 11
A17: ZZZZB | B17: 200001 | C17: 65

Sheet Property Name List
A1: propertyCode | B1: tenantId | C1: propertyName | D1: propertyId
A2: MFMGT | B2: 100007 | C2: Fleet Management Tenant | D2: 68
A3: AQACY | B3: 100021 | C3: PMSAlpha FOSSE Property 1 | D3: 53
A4: PITSS | B4: 100027 | C4: SpringHill Suites By Marriott Pittsburgh Southside Works | D4: 57
A5: CAESH | B5: 100029 | C5: SpringHill Suites By Marriott Columbia Downtown/The Vista | D5: 58
A6: BWISL | B6: 100031 | C6: SpringHill Suites by Marriott Baltimore Downtown Convention Center Area | D6: 59
A7: MCOWS | B7: 100033 | C7: SpringHill Suites by Marriott Winter Park | D7: 60
A8: CHIFO | B8: 100035 | C8: Fairfield by Marriott Inn & Suites Chicago O'Hare | D8: 61
A9: ALBTY | B9: 100037 | C9: Courtyard By Marriott Albany Troy/Waterfront | D9: 71
A10: BISCN | B10: 100039 | C10: Courtyard By Marriott Bismarck North | D10: 72
A11: MSPOX | B11: 100041 | C11: Moxy Minneapolis Uptown | D11: 75
A12: BZNAR | B12: 100043 | C12: AC Hotel Bozeman Downtown | D12: 79
A13: YYZAP | B13: 100045 | C13: Courtyard By Marriott Toronto Airport | D13: 88
... A834: SLNCY | B834: 200623 | C834: Courtyard By Marriott Salina | D834: 848

Sheet Room Count
A1: PropertyId | B1: count
A2: 1310 | B2: 123
A3: 1472 | B3: 103
A4: 1229 | B4: 133
A5: 1666 | B5: 92
A6: 491 | B6: 99
A7: 283 | B7: 78
A8: 841 | B8: 86
A9: 145 | B9: 75
A10: 238 | B10: 95
A11: 83 | B11: 174
A12: 956 | B12: 105
A13: 1085 | B13: 75
... A1719: 743 | B1719: 179
